# Handling Errors

>  要快速查看可用于错误处理的操作  see [the relevant operator decision tree](https://projectreactor.io/docs/core/release/reference/#which.errors).

In Reactive Streams,错误是 终止事件，一旦错误发生，它会终止序列，传播 到 操作链的最后一个、the `Subscriber` 、以及其 *onError* 方法。这类错误 应该 在应用级别处理

如果没有定义  onError 抛出一个 **UnsupportedOperationException**  可以通过  `Exceptions.isErrorCallbackNotImplemented` 检测跟 分类

作为错误处理 操作，Reactor 还提供了 在链条中 处理错误的 方法

```java
Flux.just(1, 2, 0)
    .map(i -> "100 / " + i + " = " + (100 / i)) //this triggers an error with 0
    .onErrorReturn("Divided by zero :("); // error handling example
```



错误处理操作 是一个终止序列，即使使用了 error-handling operator ，并不会让 序列继续，相反它将 onError信号 转换成 了 一个新序列的开始 ，换句话说：它替代了 原始序列

现在，我们可以逐一考虑各种错误处理方法。当相关时，我们与命令式编程的 try pattenr 进行并行。

## Error Handling Operators

**try catch的错误处理模型**

- Catch and return a static default value: catch 并返回静态默认值
- Catch and execute an alternative path with a fallback method：  catch，使用fallback 方法 执行替代路径
- Catch and dynamically compute a fallback value. catch 动态计算 fallback value
- Catch, wrap to a `BusinessException`, and re-throw.  catch,重新抛出
- Catch, log an error-specific message, and re-throw. catch 记录日志 重新抛出
- Use the `finally` block to clean up resources or a Java 7 “try-with-resource” construct. finally 执行资源清理

上述所有这些情况都在 Reactor中都有等价API，以 error-handling 操作形式

**try catch与 Reactor error-handling的对照**

订阅时，the `onError`  callback 回调 类似于 catch块，当异常抛出 会直接调到 catch块执行

```java
Flux<String> s = Flux.range(1, 10)
    .map(v -> doSomethingDangerous(v)) 
    .map(v -> doSecondTransform(v)); 
s.subscribe(value -> System.out.println("RECEIVED " + value), 
            error -> System.err.println("CAUGHT " + error) 
);
```

### Static Fallback Value

**trycatch模型**

```java
try {
  return doSomethingDangerous(10);
}
catch (Throwable error) {
  return "RECOVERED";
}
```

**Reactor模型**

```java
Flux.just(10)
    .map(this::doSomethingDangerous)
    .onErrorReturn("RECOVERED");
```

**Reactor Predict模型**

```java
//Recover only if the message of the exception is "boom10"

Flux.just(10)
    .map(this::doSomethingDangerous)
    .onErrorReturn(e -> e.getMessage().equals("boom10"), "recovered10"); 
```

### Fallback Method

**trycatch模型**

```java
String v1;
try {
  v1 = callExternalService("key1");
}
catch (Throwable error) {
  v1 = getFromCache("key1");
}

String v2;
try {
  v2 = callExternalService("key2");
}
catch (Throwable error) {
  v2 = getFromCache("key2");
}
```

**Reactor模型**

```java
Flux.just("key1", "key2")
    .flatMap(k -> callExternalService(k) 
        .onErrorResume(e -> getFromCache(k)) 
    );
```

**Reactor Predict模型**

```java
Flux.just("timeout1", "unknown", "key2")
    .flatMap(k -> callExternalService(k)
        .onErrorResume(error -> { 
            if (error instanceof TimeoutException) 
                return getFromCache(k);
            else if (error instanceof UnknownKeyException)  
                return registerNewEntry(k, "DEFAULT");
            else
                return Flux.error(error); 
        })
    );
```

### Dynamic Fallback Value

**trycatch模型**

```java
try {
  Value v = erroringMethod();
  return MyWrapper.fromValue(v);
}
catch (Throwable error) {
  return MyWrapper.fromError(error);
}
```

**Reactor模型**

```java
erroringFlux.onErrorResume(error -> Mono.just( 
        MyWrapper.fromError(error) 
));
```

### Catch and Rethrow

**trycatch模型**

```java
try {
  return callExternalService(k);
}
catch (Throwable error) {
  throw new BusinessException("oops, SLA exceeded", error);
}
```

**Reactor模型**

```java
Flux.just("timeout1")
    .flatMap(k -> callExternalService(k))
    .onErrorResume(original -> Flux.error(
            new BusinessException("oops, SLA exceeded", original))
    );

Flux.just("timeout1")
    .flatMap(k -> callExternalService(k))
    .onErrorMap(original -> new BusinessException("oops, SLA exceeded", original));
```

### Log or React on the Side

**trycatch模型**

```java
try {
  return callExternalService(k);
}
catch (RuntimeException error) {
  //make a record of the error
  log("uh oh, falling back, service failed for key " + k);
  throw error;
}
```

**Reactor模型**

```java
LongAdder failureStat = new LongAdder();
Flux<String> flux =
Flux.just("unknown")
    .flatMap(k -> callExternalService(k) 
        .doOnError(e -> {
            failureStat.increment();
            log("uh oh, falling back, service failed for key " + k); 
        })
        
    );
```

### Using Resources and the Finally Block

**trycatch模型**

```java
Stats stats = new Stats();
stats.startTimer();
try {
  doSomethingDangerous();
}
finally {
  stats.stopTimerAndRecordTiming();
}
try (SomeAutoCloseable disposableInstance = new SomeAutoCloseable()) {
  return disposableInstance.toString();
}

```

**Reactor模型**

Both have their Reactor equivalents: `doFinally` and `using`.

**doFinally()**

```java
Stats stats = new Stats();
LongAdder statsCancel = new LongAdder();

Flux<String> flux =
Flux.just("foo", "bar")
    .doOnSubscribe(s -> stats.startTimer())
    .doFinally(type -> { 
        stats.stopTimerAndRecordTiming();
        if (type == SignalType.CANCEL) 
          statsCancel.increment();
    })
    .take(1); 
```

**Reactive try-with-resource**

```java
Flux<String> flux =
Flux.using(
    //产生资源
        () -> disposableInstance, 
    //通过资源产生 元素对象
        disposable -> Flux.just(disposable.toString()), 
    // 清理资源的方式
        Disposable::dispose 
);
```

### 证明 *onError* 信号 导致终止

```java
Flux<String> flux =
Flux.interval(Duration.ofMillis(250))
    .map(input -> {
        if (input < 3) return "tick " + input;
        throw new RuntimeException("boom");
    })
    .onErrorReturn("Uh oh");

flux.subscribe(System.out::println);
Thread.sleep(2100); 
```

interval 在默认在 定时器上 执行 ，如果我们想在主类中运行该示例，

我们需要在此处添加 `Sleep`  调用，以便应用程序不会立即退出，而不产生任何元素

### Retrying

错误处理的另一种方式 `retry` 可以 重试 一个 正 产生错误的 序列

原理是：重新订阅 上游 *Flux*，原始的仍然终止了

```java
Flux.interval(Duration.ofMillis(250))
    .map(input -> {
        if (input < 3) return "tick " + input;
        throw new RuntimeException("boom");
    })
    .retry(1)
    .elapsed() //将每个值 与 自上一个值发出依赖的持续时间 关联在一起
    .subscribe(System.out::println, System.err::println); 

Thread.sleep(2100); 
```

```java
259,tick 0
249,tick 1
251,tick 2
506,tick 0 
248,tick 1
253,tick 2
java.lang.RuntimeException: boom
```

新的 interval 开始了，tick从0开始，在恢复的时候，需要额外等 250ms

`retry(1)`  只是 仅仅 重订阅上游  *interval* ,第二轮仍会 发生异常，再次发生异常会 将错误 传播给 下游



### RetryWhen

**Retry.from**

接收 `Flux<Retry.RetrySignal>` 返回 `Publisher<?>`

重试周期如下：

1. 当 error 发生时，会给 `Flux<RetrySignal>` 发送 信号，可以纵览所有 重试，RetrySignal 提供对 错误的访问和 相关的元信息
2. 如果 `Flux<RetrySignal>`  产生一个 值，则重试发生
3. 如果 `Flux<RetrySignal>`   complete 完成了，则错误会被吞并，重试周期会 停止，结果序列 也会完成
4. 如果 `Flux<RetrySignal>`    产生错误，重试周期 停止，使得序列 产生错误

使用 retryWhen 模拟 retry(3)

```java
//这不断产生错误，要求重试尝试。
Flux<String> flux = Flux
    .<String>error(new IllegalArgumentException()) 
//doOnError before the retry lets us log and see all failures.
    .doOnError(System.out::println) 
//The Retry is adapted from a very simple Function lambda
    .retryWhen(Retry.from(companion -> 
//我们认为前三个错误是可重复尝试的（takle(3)，然后放弃
        companion.take(3))); 
```

## Handling Exceptions in Operators or Functions

> 操作中处理异常



所有操作 和自定义的回调 都可能产生异常，惯例：未检查的异常 会被传播到 *onError*

```java
Flux.just("foo")
    .map(s -> { throw new IllegalArgumentException(s); })
    .subscribe(v -> System.out.println("GOT VALUE"),
               e -> System.out.println("ERROR: " + e));
```

在传递给 onError之前，你可以通过 *hook* 调整异常

Reactor定义了一些 必定失败的 异常，例如 `OutOfMemoryError`  ，详见*Exceptions.throwIfFatal* ，这些错误意味着 Reactor不能继续运行。

在内部，存在一些场景 ，未检查的异常 不能被传播，因为并发竞争导致的  多次触发 

*onError* *onComplete* ，无法被传播的  异常 会被 dropp掉，这种情况 可以在一定程度上 通过 使用 自定义的  hook来惯例See [Dropping Hooks](https://projectreactor.io/docs/core/release/reference/#hooks-dropping).



对于已检查的异常，同样需要 *try-catch* 块

1. catch异常，从异常中恢复
2. catch异常，使用 *Exceptions* 包装成  *unchecked* exception，抛出
3. 对于 *flatmap* 使用`Flux.error(checkedException)`

Reactor 定义了 Exceptions 工具类

1. 使用 `Exceptions.propagate`  包装异常，可以 先 调用 *thrwoIfFatal* 不包装 `RuntimeException`
2. 使用  `Exceptions.unwrap`  方法 获取 原始异常（回到 recactor-specific 专有异常的继承机构种的  根原因）



